Workbook

Sheet Compromisos RCAs
D2: Fecha actualizacion | E2: 44972
D3: Rev | E3: 1
B5: PROYECTO | C5: CONSTRUCCION ASTILLERO
B6: AREA | C6: Medio Ambiente
B7: ENCARGADO | C7: Jhony Bravo
A8: N° | B8: Componente | C8: Faena | D8: Tipo de Tarea | E8: Descripcion | F8: Documento /Accion | G8: Periodicidad | H8: Entregables | I8: Resultado | J8: Etapa Proyecto | K8: Area Responsable | L8: Observaciones
A9: 1 | B9: Obras | C9: Ejecución de tronaduras | D9: Plan/Informe | E9: Contar con plan detallado de tronaduras en base a investigación geotécnica | F9: Plan detallado de tronaduras | G9: Una vez | H9: 1 | I9: 1 | J9: Planificacion Tronadura | K9: Oficina Tecnica y Calidad
A10: 2 | B10: Obras | C10: Ejecución de tronaduras | D10: Gestion /Autorizacion | E10: Aspectos mínimos del plan de tronaduras | F10: Autorización de consumidor de explosivos. Autorizaciones transporte de Explosivos. Autorizaciones polvorines de almacenamiento de explosivos | G10: Una vez | H10: 3 | I10: 2 | J10: Planificacion Tronadura | K10: Oficina Tecnica y Calidad
A11: 3 | B11: Obras | C11: Ejecución de tronaduras | D11: Procedimiento/Informe | E11: Contratista debe contar con procedimiento de transporte, almacenamiento y manipulación de explosivos | F11: Procedimiento de transporte de explosivos. Procedimiento de almacenamiento de explosivos Procedimiento de manipulación de explosivos. | G11: Una vez | H11: 3 | I11: 3 | J11: Planificacion Tronadura | K11: Oficina Tecnica y Calidad
A12: 4 | B12: Fauna | C12: Ejecución de tronaduras | D12: Gestion/Registro | E12: Coordinar con Sernapesca, acuicultura y Seremi MA presencia de inspectores durante desarrollo de tronaduras | F12: Registros de comunicación con autoridades correspondientes | G12: Por tronadura | H12: 5 | I12: 2 | J12: Planificacion Tronadura
A13: 5 | B13: Fauna | C13: Ejecución de tronaduras | D13: Gestion/Registro | E13: Contar presencia de inspectores técnicos durante ejecución de tronaduras (según lo resuelto por autoridades) | F13: Registros de inspección técnica de tronaduras | G13: Por tronadura | H13: 5 | I13: 3 | J13: Antes de cada tronadura, Durante periodo de ejecución de tronaduras | K13: Prevencion/Medioambiente | L13: Promedio 5 tronaduras
A14: 6 | B14: Aire | C14: Transporte | D14: Registros/Informe | E14: Elaborar mensualmente registro de transporte con los distintos niveles de actividad ( vertedero mejillones) | F14: Registros de transporte de excedentes de excavación | G14: Mensual | H14: 12 | I14: 8 | J14: Excavacion borde costero | K14: Prevencion/Medioambiente | L14: 12 Meses promedio
A15: 7 | B15: Agua | C15: Insumos | D15: Gestion /potable (ord | E15: Suministro y consumo de agua potable | F15: Registros de consumo de agua potable (orden de compra, facturas) | G15: Mensual | H15: 12 | I15: 11 | J15: Toda la operación | K15: Oficina Tecnica /Administracion
A16: 8 | B16: Aire | C16: Insumos | D16: Factura/Informe | E16: Suministro y consumo de energía | F16: Factura de consumo de energía eléctrica | G16: Mensual | H16: 12 | I16: 11 | J16: Toda la operación | K16: Oficina Tecnica /Administracion
A17: 9 | B17: Aire | C17: Insumos | D17: Ordenes/Informe | E17: Suministro y consumo | F17: Ordenes de compra de hormigón. Relleno.Moldajes | G17: Mensual | H17: 12 | I17: 7 | J17: Construccion Lastre | K17: Oficina Tecnica /Administracion
A18: 10 | B18: Obras | C18: Manejo de material de exvacación | D18: Registro/Informe | E18: Retiro de material de excavación tramo terrestre de 1050-3660-753-1568 m3 | F18: Registro de volúmenes de material removido | G18: Semanal | H18: 48 | I18: 29 | J18: Excavacion borde costero | K18: Calidad
A19: 11 | B19: Aire | C19: Manejo de material de exvacación | D19: Registros/Informe | E19: Mantener registro de uso y retiro de excedentes | F19: Registros de uso y retiro de excedentes | G19: Mensual | H19: 12 | I19: 11 | J19: Excavacion borde costero | K19: Calidad
A20: 12 | B20: Aire | C20: Manejo de material de exvacación | D20: Informe/Informe | E20: Elaborar informe consolidado de uso y retiro de excedentes | F20: Informe de uso y retiro de excedentes (con registro fotográfico y georreferenciado del material usado y/o retirado) | G20: Una vez | H20: 1 | I20: 1 | J20: Excavacion borde costero | K20: Prevencion/Medioambiente
A21: 13 | B21: Aire | C21: Manejo de material de exvacación | D21: Gestion / Certificado | E21: Reportar a SMA y autoridad marítima informe de uso y retiro de excedentes de excavación | F21: Comprobante de reporte a la SMA y autoridad marítima a través del Sistema de Seguimiento Ambiental (SSA) | G21: Una vez | H21: 1 | I21: 1 | J21: Cierre de faena | K21: Prevencion/Medioambiente
A22: 14 | B22: Residuos líquidos | C22: Manejo de aguas servidas | D22: Registro/Informe | E22: Servicios higiénicos de instalación de faena conectados a sistema de alcantarillado de PTPAS | F22: Registro de inspección sistema de conexión de SSHH | G22: Una vez | H22: 1 | I22: 1 | J22: Toda la operación | K22: Prevencion/Medioambiente
A23: 15 | B23: Ruido y vibraciones | C23: Medidas de control de ruido | D23: Obra | E23: Implementar barrera acústica perimetral en sectores cercanos a receptores 3 y 4 | F23: Ejecutar obra según descricpcion. Requiere coordinacion con ECONSSA | G23: Una vez | H23: 1 | I23: 1 | J23: Inicio de obras | K23: Prevencion/Medioambiente
A24: 16 | B24: Ruido y vibraciones | C24: Medidas de control de ruido | D24: obra | E24: Configuración de barrera acústica perimetral en placas OSB de 3.6 m de altura, 15mm de espesor, revestimiento interno de fibra vidrio de 50 mm, con uniones selladas. | F24: Ejecutar Obra según especificacion | G24: Una vez | H24: 1 | I24: 1 | J24: Inicio de obras | K24: Prevencion/Medioambiente
A25: 17 | B25: Ruido y vibraciones | C25: Monitoreo de ruido y vibraciones | D25: Registros/Informe | E25: Monitoreo de rudio en medio marino durante tronaduras | F25: Registros de monitoreo de ruido submarino diario | G25: Por tronadura | H25: 5 | I25: 4 | J25: Ejecucion Tronaduras | K25: Prevencion/Medioambiente
A26: 18 | B26: Medio marino | C26: Monitoreo continuo de calidad de agua | D26: registros/Informe | E26: Parámetros a monitorear en estación móvil SS, turbidez, DO, pH, ORP y conductividad | F26: registros de monitoreo continuo de calidad de agua Diario | G26: Por tronadura | H26: 5 | I26: 5 | J26: Excavacion lecho marino | K26: Prevencion/Medioambiente
... A32: 24 | B32: Ruido y vibraciones | C32: Medidas de control de ruido | D32: Registro/Informe | E32: Aplicar cortina de burbujas durante actividades de perforación submarina | F32: Ejecutar isntalacion y funcionamiento cortinas de burbijas. Generar resgistro | G32: Por tronadura | H32: 5 | I32: 1 | J32: Perforaciones Marinas | K32: Prevencion/Medioambiente
A33: 25 | B33: Residuos sólidos | C33: Manejo de residuos sólidos | E33: Elaborar regsitro de residuos solidos con indicaciones RCA | F33: Registro de generación de residuos sólidos | G33: Mensual | H33: 12 | I33: 3 | J33: Toda la operación | K33: Prevencion/Medioambiente
A34: 26 | B34: Residuos sólidos | C34: Manejo de residuos sólidos | D34: Registros/Informe | E34: Mantener control de vectores sanitarios a través de empresa autorizada | F34: Registros de control de vectores sanitarios. Autorización sanitaria empresa de control de vectores | G34: Mensual | H34: 12 | I34: 2 | J34: Toda la operación | K34: Sitio de almacenamiento de RNP en sector playa
A35: 27 | B35: Residuos sólidos | C35: Manejo de residuos sólidos | D35: Registro/Informe | E35: Area de almacenamiento temporal de residuos con cierre perimetral de malla acma y suelo compactado | F35: Registro de inspección de acopio transitorio de RINP | G35: Mensual | H35: 12 | I35: 1 | J35: Toda la operación | K35: Sitio de almacenamiento de RNP en sector playa
A36: 28 | B36: Residuos sólidos | C36: Manejo de residuos sólidos | D36: Obtención/Informe | E36: Obtención de autorización sanitaria de funcionamiento de sitio de acopio temporal de residuos no peligrosos en frente playa | F36: Obtención de autorización sanitaria de funcionamiento de sitio de acopio temporal de residuos no peligrosos en frente playa | G36: Una vez | H36: 1 | I36: 3 | J36: Inicio de obras | K36: Sitio de almacenamiento de RNP en sector playa | N36: 1
A37: 29 | B37: Residuos sólidos | C37: Manejo de residuos sólidos | D37: Registros/Informe | E37: Residuos no peligrosos dispuestos en relleno sanitario autorizado | F37: Registros de disposición de residuos en relleno sanitario Autorización sanitaria relleno sanitario | G37: Por tronadura | H37: 5 | I37: 2 | J37: Toda la operación
A38: 30 | B38: Aire | C38: Manejo de excedentes de excavación | D38: Registros/Informe | E38: Exedentes de excavación en área de acopio temporal | F38: Registros de retiro de excedentes de excavación | G38: Semanal | H38: 48 | I38: 1 | J38: Toda la operación | K38: Acopio temporal de excedentes de excavación
A39: 31 | B39: Aire | C39: Medidas de control de material particulado | D39: Registro/Informe | E39: Ver indicaciones y detalle registro | F39: Registro de inspección según indicaciones RCA | G39: Semanal | H39: 48 | I39: 1 | J39: Toda la operación | K39: Frente de trabajo sector playa
A40: 32 | B40: Aire | C40: Medidas de control de material particulado | D40: Procedimiento/Informe | E40: Elaborar Procedimiento de control de polvo en obra | F40: Procedimiento de control de polvo en obra | G40: Una vez | H40: 1 | I40: 4 | J40: Toda la operación | K40: Prevencion/Medioambiente
A41: 33 | B41: Ruido y vibraciones | C41: Medidas de control de ruido | D41: Registro/Informe | E41: Otras medidas de control y manejo de emisiones acústicas | F41: Registro de verificación de medidas de control y manejo de emisiones acústicas. | G41: Semanal | H41: 48 | I41: 2 | J41: Toda la operación
A42: 34 | B42: Residuos líquidos | C42: Manejo de aguas servidas | D42: Registro/Informe | E42: Implementar PTAS modular con disposición de aguas tratadas hacia cámara conectada a PEAS Pinares o en cámara de carga de PTPAS. | F42: Registro de instalación y funcionamiento de PTAS modular | G42: Una vez | H42: 1 | I42: 1 | J42: Toda la operación | K42: PTAS temporal frente playa
A43: 35 | B43: residuos líquidos | C43: Manejo de aguas servidas | D43: Registro/Informe | E43: Disponer de baños químicos en frente de trabajo sector playa | F43: Disponer baños quimicos Frente playa | G43: Una vez | H43: 1 | I43: 2 | J43: Toda la operación | K43: Frente de trabajo sector playa
A44: 36 | B44: Residuos sólidos | C44: Manejo de residuos sólidos | D44: Respaldos/Informe | E44: Efectuar declaración de residuos en SINADER de Ventanilla única de RETC | F44: Respaldos mensuales y anuales de declaración de residuos en SINADER | G44: Mensual | H44: 12 | I44: 1 | J44: Toda la operación
A45: 37 | B45: Residuos sólidos | C45: Manejo de residuos sólidos | D45: Registro/Informe | E45: RSD acumulados en contenedores con tapa, cerrados y bolsa en interior, en instalación de faena | F45: Registro de inspección de manejo de RSD en faena | G45: Semanal | H45: 48 | I45: 3 | J45: Toda la operación
A46: 38 | B46: Residuos sólidos | C46: Manejo de residuos sólidos | D46: Respaldo/Informe | E46: RSD retirados al menos 3 veces por semana por servicio municipal | F46: Respaldo Report de servicio de retiro y transporte de residuos | G46: Semanal | H46: 48 | I46: 2 | J46: Toda la operación
A47: 39 | B47: residuos sólidos | C47: Manejo de RESPEL | D47: Gestion /RESPEL en bo | E47: Tipo y cantidad de RESPEL generados | F47: Registros de RESPEL en bodega. Regitro de inspeccioen RESPEL | G47: Mensual | H47: 12 | I47: 1 | J47: Toda la operación
...

Sheet GEN
A2: ='Compromisos RCAs'!$B$8 -> Componente | C2: Entregables | D2: Resultado | E2: %Avance
A3: GEN 1 | B3: Autorización de DOP | C3: ='Compromisos RCAs'!H93 -> 1 | D3: ='Compromisos RCAs'!I93 -> 1 | E3: =D3/C3 -> 1
A4: GEN 2 | B4: Registro de reunión con bomberos | C4: ='Compromisos RCAs'!H100 -> 1 | D4: 1 | E4: =D4/C4 -> 1
A5: GEN 3 | B5: Registro de entrega de plano de sala de generadores a bomberos | C5: ='Compromisos RCAs'!H101 -> 1 | D5: 1 | E5: =D5/C5 -> 1
A6: GEN 4 | B6: Registro de inspección de extintores en planta | C6: ='Compromisos RCAs'!H102 -> 12 | D6: 7 | E6: =D6/C6 -> 0.58333333
A7: GEN 5 | B7: Reporte de ejecución de simulacro. | C7: ='Compromisos RCAs'!H103 -> 12 | D7: 3 | E7: =D7/C7 -> 0.25
A8: GEN 6 | B8: Lista firmada de asistentes a capacitaciones acerca de uso y manejo de extintores | C8: ='Compromisos RCAs'!H104 -> 2 | D8: 2 | E8: =D8/C8 -> 1
A9: GEN 7 | B9: Respaldo de informe de ejecución de faena mínima de inicio de obras | C9: ='Compromisos RCAs'!H110 -> 1 | D9: 1 | E9: =D9/C9 -> 1
A10: GEN 8 | B10: Respaldo de aviso de inicio de fase de construcción | C10: ='Compromisos RCAs'!H111 -> 1 | D10: 1 | E10: =D10/C10 -> 1
A11: GEN 9 | B11: Entregar Plan de gestion ambiental | C11: ='Compromisos RCAs'!H112 -> 1 | D11: ='Compromisos RCAs'!I112 -> 1 | E11: =D11/C11 -> 1
A12: GEN 10 | B12: Elaborar matriz de seguimiento ambiental | C12: ='Compromisos RCAs'!H113 -> 1 | D12: ='Compromisos RCAs'!I113 -> 1 | E12: =D12/C12 -> 1

Sheet MEDHU
A2: ='Compromisos RCAs'!$B$8 -> Componente | C2: Entregables | D2: Resultado | E2: %Avance
A3: MEDHUM 1 | B3: Gestion de diseño, instalacion y coordinacion con autoridad para instalacion de señaletica durante tronadura | C3: ='Compromisos RCAs'!H73 -> 5 | D3: 3 | E3: =D3/C3 -> 0.6
A4: MEDHUM 2 | B4: Registro documental y fotográfico fechado y georreferenciado de retiro de señalética. | C4: ='Compromisos RCAs'!H74 -> 5 | D4: 4 | E4: =D4/C4 -> 0.8
A5: MEDHUM 3 | B5: Minutas de reuniones y/o envíos de información con Dirección de tránsito. Requisitos técnicos aprobados por Dirección de tránsito | C5: ='Compromisos RCAs'!H75 -> 5 | D5: 2 | E5: =D5/C5 -> 0.4
A6: MEDHUM 4 | B6: Registro documental y fotográfico fechado y georreferenciado de intervención de intersecciones. | C6: ='Compromisos RCAs'!H76 -> 48 | D6: 34 | E6: =D6/C6 -> 0.70833333
A7: MEDHUM 5 | B7: ='Compromisos RCAs'!$F$79 -> Protocolo de comunicación comunidad CV elaborado y formalizado | C7: ='Compromisos RCAs'!H79 -> 1 | D7: 1 | E7: =D7/C7 -> 1
A8: MEDHUM 6 | B8: Contratos con empresas de la región. Prsentar contratos ECONSSA | C8: ='Compromisos RCAs'!H80 -> 1 | D8: ='Compromisos RCAs'!I80 -> 1 | E8: =D8/C8 -> 1
A9: MEDHUM 7 | B9: Nómina actualizada de trabajadores contratados (directos, contratistas y subcontratistas) con indicación de domicilio e indicador de % respecto del total | C9: ='Compromisos RCAs'!H81 -> 12 | D9: 12 | E9: =D9/C9 -> 1
A10: MEDHUM 8 | B10: Nómina actualizada de trabajadores contratados (directos, contratistas y subcontratistas) con indicación de sexo. | C10: ='Compromisos RCAs'!H82 -> 12 | D10: 12 | E10: =D10/C10 -> 1

Sheet ARQ
A3: ='Compromisos RCAs'!$B$8 -> Componente | C3: Entregables | D3: Resultado | E3: %Avance
A4: ARQ1 | B4: Registros de inducciones con listado firmado de asistentes y relator | C4: ='Compromisos RCAs'!H58 -> 1 | D4: ='Compromisos RCAs'!I58 -> 1
A5: ARQ2 | B5: Informes de monitoreo arqueológico y registros de bitácora de inspección diaria | C5: ='Compromisos RCAs'!H59 -> 12 | D5: ='Compromisos RCAs'!I59 -> 11
A6: ARQ3 | B6: CV y certificado de Arqueologo/a o licenciado/a en arqueología a cargo del monitoreo y charlas de inducción | C6: ='Compromisos RCAs'!H60 -> 1 | D6: ='Compromisos RCAs'!I60 -> 1
A7: ARQ4 | B7: Informe mensual de monitoreo con contenidos indicados con firma de arqueólogo a cargo. | C7: ='Compromisos RCAs'!H61 -> 12 | D7: ='Compromisos RCAs'!I61 -> 7
A8: ARQ5 | B8: Comprobante de reporte a la SMA y CMN a través del Sistema de Seguimiento Ambiental (SSA) | C8: ='Compromisos RCAs'!H62 -> 12 | D8: ='Compromisos RCAs'!I62 -> 8

Sheet SUSPEL
A2: SUSTANCIAS PELIGROSAS
A3: ='Compromisos RCAs'!$B$8 -> Componente | C3: Entregables | D3: Resultado | E3: %Avance
A4: Suspel 1 | B4: ='Compromisos RCAs'!$F$57 -> Registro y copia de certificado del contratista de autorización para el transporte de explosivos. | C4: ='Compromisos RCAs'!H57 -> 5 | D4: ='Compromisos RCAs'!I57 -> 5
A5: Suspel 2 | B5: Registros de inspección de mantención de atril con valdes de arena | C5: ='Compromisos RCAs'!H105 -> 12 | D5: ='Compromisos RCAs'!I105 -> 12
A6: Suspel 3 | B6: Autorización SEC empresa de transporte de combustibles | C6: ='Compromisos RCAs'!H106 -> 12 | D6: ='Compromisos RCAs'!I106 -> 12
A7: Suspel 4 | B7: Lista firmada de asistentes a capacitaciones con indicación de contenidos y registro fotográfico | C7: ='Compromisos RCAs'!H107 -> 1 | D7: ='Compromisos RCAs'!I107 -> 1
A8: Suspel 5 | B8: Procedimiento carga de combustible. | C8: ='Compromisos RCAs'!H108 -> 1 | D8: ='Compromisos RCAs'!I108 -> 1
A9: Suspel 6 | B9: Procedimiento de trasvasije de combustible. Registros de inspección de actividad de trasvasije de combustible | C9: ='Compromisos RCAs'!H109 -> 4 | D9: ='Compromisos RCAs'!I109 -> 3

Sheet Medio Marino
A2: ='Compromisos RCAs'!$B$8 -> Componente | C2: Unidades | D2: Resultado | E2: %Avance
A3: MEDMA 1 | B3: registros de monitoreo continuo de calidad de agua | C3: ='Compromisos RCAs'!H26 -> 5 | D3: ='Compromisos RCAs'!I26 -> 5 | E3: =C3/D3 -> 1
A4: MEDMA 2 | B4: Comprobante de envío de registros de monitoreo continuo de calidad de agua a SMA a través del Sistema de Seguimiento Ambiental (SSA) | C4: ='Compromisos RCAs'!H27 -> 5 | D4: ='Compromisos RCAs'!I27 -> 5 | E4: =C4/D4 -> 1
A5: MEDMA 3 | B5: Informe de monitoreo de calidad de agua con indicación de parámetros a monitorear | C5: ='Compromisos RCAs'!H63 -> 20 | D5: ='Compromisos RCAs'!I63 -> 20 | E5: =C5/D5 -> 1
A6: MEDMA 4 | B6: Informe de monitoreo de calidad de agua con indicación georreferenciada de estaciones de monitoreo | C6: ='Compromisos RCAs'!H64 -> 20 | D6: ='Compromisos RCAs'!I64 -> 20 | E6: =C6/D6 -> 1
A7: MEDMA 5 | B7: Comprobante de reporte de informe de monitoreo de calidad de agua a la SMA a través del Sistema de Seguimiento Ambiental (SSA) | C7: ='Compromisos RCAs'!H65 -> 20 | D7: ='Compromisos RCAs'!I65 -> 20 | E7: =C7/D7 -> 1
A8: MEDMA 6 | B8: Informe de monitoreo de comunidades intermareales de fondos duros con indicación de parámetros a monitorear | C8: ='Compromisos RCAs'!H66 -> 20 | D8: ='Compromisos RCAs'!I66 -> 20 | E8: =C8/D8 -> 1
A9: MEDMA 7 | B9: Comprobante de reporte de informe de monitoreo de de comunidades intermareales de fondos duros a la SMA a través del Sistema de Seguimiento Ambiental (SSA) | C9: ='Compromisos RCAs'!H67 -> 20 | D9: ='Compromisos RCAs'!I67 -> 20 | E9: =C9/D9 -> 1
A10: MEDMA 8 | B10: Informe de monitoreo de comunidades submareales de fondos blandos con indicación de parámetros a monitorear | C10: ='Compromisos RCAs'!H68 -> 20 | D10: ='Compromisos RCAs'!I68 -> 20 | E10: =C10/D10 -> 1
A11: MEDMA 9 | B11: Informe de monitoreo de comunidades submareales de fondos blandos con indicación georreferenciada de estaciones de monitoreo | C11: ='Compromisos RCAs'!H69 -> 20 | D11: ='Compromisos RCAs'!I69 -> 20 | E11: =C11/D11 -> 1
A12: MEDMA 10 | B12: Comprobante de reporte de informe de monitoreo de de comunidades submareales de fondos blandos a la SMA a través del Sistema de Seguimiento Ambiental (SSA) | C12: ='Compromisos RCAs'!H70 -> 20 | D12: ='Compromisos RCAs'!I70 -> 20 | E12: =C12/D12 -> 1
A13: MEDMA 11 | B13: Autorización SHOA para actividades del PVA | C13: ='Compromisos RCAs'!H94 -> 1 | D13: ='Compromisos RCAs'!I94 -> 1 | E13: =C13/D13 -> 1
A14: MEDMA 12 | B14: Respaldo de aviso de inicio de obra a Capitanía de Puerto Antofagasta | C14: ='Compromisos RCAs'!H95 -> 1 | D14: ='Compromisos RCAs'!I95 -> 1 | E14: =C14/D14 -> 1
A15: MEDMA 13 | B15: Autorización de Capitanía de Puerto Antofagasta para faenas de trabajo marítimo en embarcaciones y artefactos navales | C15: ='Compromisos RCAs'!H96 -> 1 | D15: ='Compromisos RCAs'!I96 -> 1 | E15: =C15/D15 -> 1
A16: MEDMA 14 | B16: Autorización de capítanía de Puerto Antofagasta para faenas de trabajo submarino de buceo | C16: ='Compromisos RCAs'!H97 -> 1 | D16: ='Compromisos RCAs'!I97 -> 1 | E16: =C16/D16 -> 1
A17: MEDMA 15 | B17: Autorización de Gobernación Marítima de Antofagasta para ejecución de pruebas hidráulicas y/o hidrostáticas de emisario y descarga de emergencia | C17: ='Compromisos RCAs'!H98 -> 1 | D17: ='Compromisos RCAs'!I98 -> 1 | E17: =C17/D17 -> 1

Sheet RESLIQ
A2: ='Compromisos RCAs'!$B$8 -> Componente | C2: Entregables | D2: Resultado | E2: %Avance
A3: RESLIQ 1 | B3: Registro de inspección sistema de conexión de SSHH | C3: ='Compromisos RCAs'!H22 -> 1 | D3: ='Compromisos RCAs'!I22 -> 1 | E3: =D3/C3 -> 1
A4: RESLIQ 2 | B4: Registro de instalación y funcionamiento de PTAS modular | C4: ='Compromisos RCAs'!H42 -> 1 | D4: ='Compromisos RCAs'!I42 -> 1 | E4: =D4/C4 -> 1
A5: RESLIQ 3 | B5: Disponer baños quimicos Frente playa | C5: ='Compromisos RCAs'!H43 -> 1 | D5: 0 | E5: =D5/C5 -> 0
A6: RESLIQ 4 | B6: Respaldos de lavado de vehículos y maquinarias en instalaciones externas | C6: ='Compromisos RCAs'!H88 -> 12 | D6: 9 | E6: =D6/C6 -> 0.75

Sheet RYB
A1: RUIDO Y VIBRACIONES
A2: ='Compromisos RCAs'!$B$8 -> Componente | C2: Entregables | D2: Resultado | E2: %Avance
A3: RYB 1 | B3: Ejecutar obra según descricpcion. Requiere coordinacion con ECONSSA | C3: ='Compromisos RCAs'!H23 -> 1 | D3: ='Compromisos RCAs'!I23 -> 1 | E3: =D3/C3 -> 1
A4: RYB 2 | B4: Ejecutar Obra según especificacion | C4: ='Compromisos RCAs'!H24 -> 1 | D4: ='Compromisos RCAs'!I24 -> 1 | E4: =D4/C4 -> 1
A5: RYB 3 | B5: Registros de monitoreo de ruido submarino diario | C5: ='Compromisos RCAs'!H25 -> 5 | D5: ='Compromisos RCAs'!I25 -> 4 | E5: =D5/C5 -> 0.8
A6: RYB 4 | B6: Registros de ejecución de tronaduras con indicaciónes | C6: ='Compromisos RCAs'!H29 -> 5 | D6: ='Compromisos RCAs'!I29 -> 1 | E6: =D6/C6 -> 0.2
A7: RYB 5 | B7: Informe trimestral de medidas de control de ruidos submarinos | C7: ='Compromisos RCAs'!H30 -> 4 | D7: ='Compromisos RCAs'!I30 -> 3 | E7: =D7/C7 -> 0.75
A8: RYB 6 | B8: Comprobante de reporte a la SMA a través del Sistema de Seguimiento Ambiental (SSA) | C8: ='Compromisos RCAs'!H31 -> 4 | D8: ='Compromisos RCAs'!I31 -> 2 | E8: =D8/C8 -> 0.5
A9: RYB 7 | B9: Ejecutar isntalacion y funcionamiento cortinas de burbijas. Generar resgistro | C9: ='Compromisos RCAs'!H32 -> 5 | D9: ='Compromisos RCAs'!I32 -> 1 | E9: =D9/C9 -> 0.2
A10: RYB 8 | B10: Registro de verificación de medidas de control y manejo de emisiones acústicas. | C10: ='Compromisos RCAs'!H41 -> 48 | D10: ='Compromisos RCAs'!I41 -> 2 | E10: =D10/C10 -> 0.041666667
A11: RYB 9 | B11: Informe de monitoreo que incluya registro fotográfico y georrerferenciado de puntos de monitoreo | C11: ='Compromisos RCAs'!H77 -> 25 | D11: ='Compromisos RCAs'!I77 -> 24 | E11: =D11/C11 -> 0.96
A12: RYB 10 | B12: Comprobante de reporte a la SMA a través del Sistema de Seguimiento Ambiental (SSA) | C12: ='Compromisos RCAs'!H78 -> 25 | D12: ='Compromisos RCAs'!I78 -> 25 | E12: =D12/C12 -> 1
A13: RYB 11 | B13: Registros de uso de protectores auditivos en faena | C13: ='Compromisos RCAs'!H90 -> 12 | D13: ='Compromisos RCAs'!I90 -> 10 | E13: =D13/C13 -> 0.83333333

Sheet RESOL
A2: ='Compromisos RCAs'!$B$8 -> Componente | C2: Entregable | D2: Resultado | E2: %Avance
A3: RESOL 1 | B3: Registro de generación de residuos sólidos | C3: ='Compromisos RCAs'!H33 -> 12 | D3: ='Compromisos RCAs'!I33 -> 3 | E3: =D3/C3 -> 0.25
A4: RESOL 2 | B4: Registros de control de vectores sanitarios. Autorización sanitaria empresa de control de vectores | C4: ='Compromisos RCAs'!H34 -> 12 | D4: ='Compromisos RCAs'!I34 -> 2 | E4: =D4/C4 -> 0.16666667
A5: RESOL 3 | B5: Registro de inspección de acopio transitorio de RINP | C5: ='Compromisos RCAs'!H35 -> 12 | D5: ='Compromisos RCAs'!I35 -> 1 | E5: =D5/C5 -> 0.083333333
A6: RESOL 4 | B6: Obtención de autorización sanitaria de funcionamiento de sitio de acopio temporal de residuos no peligrosos en frente playa | C6: ='Compromisos RCAs'!H36 -> 1 | D6: ='Compromisos RCAs'!I36 -> 3 | E6: =D6/C6 -> 3
A7: RESOL 5 | B7: Registros de disposición de residuos en relleno sanitario Autorización sanitaria relleno sanitario | C7: ='Compromisos RCAs'!H37 -> 5 | D7: ='Compromisos RCAs'!I37 -> 2 | E7: =D7/C7 -> 0.4
A8: RESOL 6 | B8: Respaldos mensuales y anuales de declaración de residuos en SINADER | C8: ='Compromisos RCAs'!H44 -> 12 | D8: ='Compromisos RCAs'!I44 -> 1 | E8: =D8/C8 -> 0.083333333
A9: RESOL 7 | B9: Registro de inspección de manejo de RSD en faena | C9: ='Compromisos RCAs'!H45 -> 48 | D9: ='Compromisos RCAs'!I45 -> 3 | E9: =D9/C9 -> 0.0625
A10: RESOL 8 | B10: Respaldo Report de servicio de retiro y transporte de residuos | C10: ='Compromisos RCAs'!H46 -> 48 | D10: ='Compromisos RCAs'!I46 -> 2 | E10: =D10/C10 -> 0.041666667
A11: RESOL 9 | B11: Registros de RESPEL en bodega. Regitro de inspeccioen RESPEL | C11: ='Compromisos RCAs'!H47 -> 12 | D11: ='Compromisos RCAs'!I47 -> 1 | E11: =D11/C11 -> 0.083333333
A12: RESOL 10 | B12: Registros de ingreso y egreso de RESPEL en bodega, indicando tipo, cantidad y peligrosidad. | C12: ='Compromisos RCAs'!H48 -> 12 | D12: ='Compromisos RCAs'!I48 -> 3 | E12: =D12/C12 -> 0.25
A13: RESOL 11 | B13: Registros de ingreso y egreso de RESPEL en bodega, indicando tipo, cantidad y peligrosidad. | C13: ='Compromisos RCAs'!H49 -> 12 | D13: ='Compromisos RCAs'!I49 -> 3 | E13: =D13/C13 -> 0.25
A14: RESOL 12 | B14: Autorización sanitaria empresa de transporte de RESPEL Respaldos SIDREP | C14: ='Compromisos RCAs'!H50 -> 1 | D14: ='Compromisos RCAs'!I50 -> 3 | E14: =D14/C14 -> 3
A15: RESOL 13 | B15: Autorización sanitaria empresa de disposición final de RESPEL Respaldos SIDREP | C15: ='Compromisos RCAs'!H51 -> 1 | D15: ='Compromisos RCAs'!I51 -> 4 | E15: =D15/C15 -> 4
A16: RESOL 14 | B16: Respaldo declaración anual en ventanilla única RETC | C16: ='Compromisos RCAs'!H52 -> 1 | D16: ='Compromisos RCAs'!I52 -> 4 | E16: =D16/C16 -> 4
A17: RESOL 15 | B17: Autorización sanitaria de funcionamiento Bodega de RESPEL | C17: ='Compromisos RCAs'!H53 -> 1 | D17: ='Compromisos RCAs'!I53 -> 2 | E17: =D17/C17 -> 2
A18: RESOL 16 | B18: Regoistros de generación de RSNP durante construcción | C18: ='Compromisos RCAs'!H89 -> 12 | D18: 11 | E18: =D18/C18 -> 0.91666667
A19: RESOL 17 | B19: Registro de inspección de zona de almacenamiento de residuos al interior planta | C19: ='Compromisos RCAs'!H91 -> 12 | D19: 6 | E19: =D19/C19 -> 0.5
A20: RESOL 18 | B20: Autorización sanitaria de Almacenamiento de residuos no peligrosos en sitio al interior de PTPAS | C20: ='Compromisos RCAs'!H92 -> 1 | D20: 1 | E20: =D20/C20 -> 1

Sheet Aguas 
A2: ='Compromisos RCAs'!$B$8 -> Componente | C2: Entregables | D2: Resultado | E2: %Avance
A3: Agua 1 | B3: Registros de consumo de agua potable (orden de compra, facturas) | C3: ='Compromisos RCAs'!H15 -> 12 | D3: ='Compromisos RCAs'!I15 -> 11 | E3: =D3/C3 -> 0.91666667
A4: Agua 2 | B4: Registros de consumo de agua potable | C4: ='Compromisos RCAs'!H54 -> 12 | D4: ='Compromisos RCAs'!I54 -> 4 | E4: =D4/C4 -> 0.33333333
A5: Agua 3 | B5: Copias de las facturas de cobro del agua potable que proveedores autorizados. | C5: ='Compromisos RCAs'!H55 -> 12 | D5: 11 | E5: =D5/C5 -> 0.91666667
A6: Agua 4 | B6: Registros de compra de agua potable en dispensadores.Autorización sanitaria empresa suminstro de dispensador de bidones. | C6: ='Compromisos RCAs'!H56 -> 2 | D6: 2 | E6: =D6/C6 -> 1

Sheet Aire
A2: ='Compromisos RCAs'!$B$8 -> Componente | C2: Entregables | D2: Resultado | E2: %Avance
A3: Aire 1 | B3: Registros de transporte de excedentes excavación | C3: ='Compromisos RCAs'!H14 -> 12 | D3: ='Compromisos RCAs'!I14 -> 8 | E3: =D3/C3 -> 0.66666667
A4: Aire 2 | B4: Factura de consumo de energía eléctrica | C4: ='Compromisos RCAs'!H16 -> 12 | D4: ='Compromisos RCAs'!I16 -> 11 | E4: =D4/C4 -> 0.91666667
A5: Aire 3 | B5: Ordenes de compra de hormigón. Relleno.Moldajes | C5: ='Compromisos RCAs'!H17 -> 12 | D5: ='Compromisos RCAs'!I17 -> 7 | E5: =D5/C5 -> 0.58333333
A6: Aire 4 | B6: Registros de uso y retiro de excedentes | C6: ='Compromisos RCAs'!H19 -> 12 | D6: ='Compromisos RCAs'!I19 -> 11 | E6: =D6/C6 -> 0.91666667
A7: Aire 5 | B7: Informe de uso y retiro de excedentes (con registro fotográfico y georreferenciado del material usado y/o retirado) | C7: ='Compromisos RCAs'!H20 -> 1 | D7: ='Compromisos RCAs'!I20 -> 1 | E7: =D7/C7 -> 1
A8: Aire 6 | B8: Comprobante de reporte a la SMA y autoridad marítima a través del Sistema de Seguimiento Ambiental (SSA) | C8: ='Compromisos RCAs'!H21 -> 1 | D8: ='Compromisos RCAs'!I21 -> 1 | E8: =D8/C8 -> 1
A9: Aire 7 | B9: Registros de retiro de excedentes de excavación | C9: ='Compromisos RCAs'!H38 -> 48 | D9: ='Compromisos RCAs'!I38 -> 1 | E9: =D9/C9 -> 0.020833333
A10: Aire 8 | B10: Registro de inspección según indicaciones RCA | C10: ='Compromisos RCAs'!H39 -> 48 | D10: ='Compromisos RCAs'!I39 -> 1 | E10: =D10/C10 -> 0.020833333
A11: Aire 9 | B11: Procedimiento de control de polvo en obra | C11: ='Compromisos RCAs'!H40 -> 1 | D11: 1 | E11: =D11/C11 -> 1

Sheet Fauna
A3: ='Compromisos RCAs'!$B$8 -> Componente | C3: Entregables | D3: Resultado | E3: %Avance
A4: Fauna 1 | B4: ='Compromisos RCAs'!F12 -> Registros de comunicación con autoridades correspondientes | C4: ='Compromisos RCAs'!H12 -> 5 | D4: ='Compromisos RCAs'!I12 -> 2 | E4: =D4/C4 -> 0.4
A5: Fauna 2 | B5: ='Compromisos RCAs'!F13 -> Registros de inspección técnica de tronaduras | C5: ='Compromisos RCAs'!H13 -> 5 | D5: ='Compromisos RCAs'!I13 -> 3 | E5: =D5/C5 -> 0.6
A6: Fauna 3 | B6: Realizar campaña de verificacion y perturbacion controlada previo y durante tronaduras | C6: ='Compromisos RCAs'!H28 -> 5 | D6: ='Compromisos RCAs'!I28 -> 5 | E6: =D6/C6 -> 1
A7: Fauna 4 | B7: Informe de ejecución de perturbación controlada con indicación de transectas dentro del área de exclusión | C7: ='Compromisos RCAs'!H83 -> 1 | D7: 1 | E7: =D7/C7 -> 1
A8: Fauna 5 | B8: Respaldo de envío de informa a través de plataforma SSA de SMA | C8: ='Compromisos RCAs'!H84 -> 1 | D8: 1 | E8: =D8/C8 -> 1
A9: Fauna 6 | B9: Informe con detalle de ejecución de medida de protección de aves | C9: ='Compromisos RCAs'!H85 -> 1 | D9: 1 | E9: =D9/C9 -> 1
A10: Fauna 7 | B10: Respaldo de envío de informa a través de plataforma SSA de SMA | C10: ='Compromisos RCAs'!H86 -> 1 | D10: 1 | E10: =D10/C10 -> 1

Sheet Obras
A2: ='Compromisos RCAs'!$B$8 -> Componente | C2: ='Compromisos RCAs'!H8 -> Entregables | D2: ='Compromisos RCAs'!I8 -> Resultado | E2: %Avance
A3: Obras 1 | B3: Plan detallado de tronaduras | C3: ='Compromisos RCAs'!H9 -> 1 | D3: 0 | E3: =D3/C3 -> 0
A4: Obras 2 | B4: Autorización de consumidor de explosivos. Autorizaciones transporte de Explosivos. Autorizaciones polvorines de almacenamiento de explosivos | C4: ='Compromisos RCAs'!H10 -> 3 | D4: 0 | E4: =D4/C4 -> 0
A5: Obras 3 | B5: Procedimiento de transporte de explosivos. Procedimiento de almacenamiento de explosivos Procedimiento de manipulación de explosivos. | C5: ='Compromisos RCAs'!H11 -> 3 | D5: 0 | E5: =D5/C5 -> 0
A6: Obras 4 | B6: Registro de volúmenes de material removido | C6: ='Compromisos RCAs'!H18 -> 48 | D6: ='Compromisos RCAs'!I18 -> 29 | E6: =D6/C6 -> 0.60416667
A7: Obras 5 | B7: Autorización de inicio de obras sector Playa | C7: ='Compromisos RCAs'!H71 -> 2 | D7: ='Compromisos RCAs'!I71 -> 2 | E7: =D7/C7 -> 1
A8: Obras 6 | B8: Comprobante de remisión de autorización DOM a SMA | C8: ='Compromisos RCAs'!H72 -> 1 | D8: 1 | E8: =D8/C8 -> 1
A9: Obras 7 | B9: Registros de inpección instalación de faenas sector PTPAS | C9: ='Compromisos RCAs'!H87 -> 12 | D9: 7 | E9: =D9/C9 -> 0.58333333
A10: Obras 8 | B10: Respaldo de envío a Seremi BBNN de informe de proveedores de hormigón (incluyendo ODC). | C10: ='Compromisos RCAs'!H99 -> 12 | D10: 8 | E10: =D10/C10 -> 0.66666667
